  File "routine4.py", line 19
    if m="55":
        ^
SyntaxError: invalid syntax
=====
Traceback (most recent call last):
  File "/home/ubuntu/test/ItChat/itchat/components/login.py", line 248, in maintain_loop
    i = sync_check(self)
  File "/home/ubuntu/test/ItChat/itchat/components/login.py", line 308, in sync_check
    if not isinstance(e.args[0].args[1], BadStatusLine):
IndexError: tuple index out of range

Traceback (most recent call last):
  File "/home/ubuntu/test/ItChat/itchat/components/login.py", line 248, in maintain_loop
    i = sync_check(self)
  File "/home/ubuntu/test/ItChat/itchat/components/login.py", line 308, in sync_check
    if not isinstance(e.args[0].args[1], BadStatusLine):
IndexError: tuple index out of range

Traceback (most recent call last):
  File "/home/ubuntu/test/ItChat/itchat/components/login.py", line 248, in maintain_loop
    i = sync_check(self)
  File "/home/ubuntu/test/ItChat/itchat/components/login.py", line 308, in sync_check
    if not isinstance(e.args[0].args[1], BadStatusLine):
IndexError: tuple index out of range

Traceback (most recent call last):
  File "/home/ubuntu/test/ItChat/itchat/components/login.py", line 248, in maintain_loop
    i = sync_check(self)
  File "/home/ubuntu/test/ItChat/itchat/components/login.py", line 308, in sync_check
    if not isinstance(e.args[0].args[1], BadStatusLine):
IndexError: tuple index out of range

Traceback (most recent call last):
  File "/home/ubuntu/test/ItChat/itchat/components/login.py", line 248, in maintain_loop
    i = sync_check(self)
  File "/home/ubuntu/test/ItChat/itchat/components/login.py", line 308, in sync_check
    if not isinstance(e.args[0].args[1], BadStatusLine):
IndexError: tuple index out of range

Traceback (most recent call last):
  File "/home/ubuntu/test/ItChat/itchat/components/login.py", line 248, in maintain_loop
    i = sync_check(self)
  File "/home/ubuntu/test/ItChat/itchat/components/login.py", line 308, in sync_check
    if not isinstance(e.args[0].args[1], BadStatusLine):
IndexError: tuple index out of range

LOG OUT!
Failed to fetch contact, that may because of the amount of your chatrooms
Failed to fetch contact, that may because of the amount of your chatrooms
Failed to fetch contact, that may because of the amount of your chatrooms
Please press confirm on your phone.
Loading the contact, this may take a little while.
[3J[H[2JLogin successfully as Êü≥Âçöüìà
Traceback (most recent call last):
  File "/home/ubuntu/test/ItChat/itchat/components/login.py", line 254, in maintain_loop
    msgList, contactList = self.get_msg()
  File "/home/ubuntu/test/ItChat/itchat/components/login.py", line 336, in get_msg
    r = self.s.post(url, data=json.dumps(data), headers=headers, timeout=config.TIMEOUT)
  File "/home/ubuntu/.local/lib/python2.7/site-packages/requests/sessions.py", line 572, in post
    return self.request('POST', url, data=data, json=json, **kwargs)
  File "/home/ubuntu/.local/lib/python2.7/site-packages/requests/sessions.py", line 524, in request
    resp = self.send(prep, **send_kwargs)
  File "/home/ubuntu/.local/lib/python2.7/site-packages/requests/sessions.py", line 637, in send
    r = adapter.send(request, **kwargs)
  File "/home/ubuntu/.local/lib/python2.7/site-packages/requests/adapters.py", line 498, in send
    raise ConnectionError(err, request=request)
ConnectionError: ('Connection aborted.', BadStatusLine("''",))

Traceback (most recent call last):
  File "/home/ubuntu/test/ItChat/itchat/components/login.py", line 248, in maintain_loop
    i = sync_check(self)
  File "/home/ubuntu/test/ItChat/itchat/components/login.py", line 308, in sync_check
    if not isinstance(e.args[0].args[1], BadStatusLine):
IndexError: tuple index out of range

Traceback (most recent call last):
  File "/home/ubuntu/test/ItChat/itchat/components/login.py", line 248, in maintain_loop
    i = sync_check(self)
  File "/home/ubuntu/test/ItChat/itchat/components/login.py", line 308, in sync_check
    if not isinstance(e.args[0].args[1], BadStatusLine):
IndexError: tuple index out of range

Traceback (most recent call last):
  File "/home/ubuntu/test/ItChat/itchat/components/login.py", line 248, in maintain_loop
    i = sync_check(self)
  File "/home/ubuntu/test/ItChat/itchat/components/login.py", line 308, in sync_check
    if not isinstance(e.args[0].args[1], BadStatusLine):
IndexError: tuple index out of range

Traceback (most recent call last):
  File "/home/ubuntu/test/ItChat/itchat/components/login.py", line 248, in maintain_loop
    i = sync_check(self)
  File "/home/ubuntu/test/ItChat/itchat/components/login.py", line 308, in sync_check
    if not isinstance(e.args[0].args[1], BadStatusLine):
IndexError: tuple index out of range

Traceback (most recent call last):
  File "/home/ubuntu/test/ItChat/itchat/components/login.py", line 248, in maintain_loop
    i = sync_check(self)
  File "/home/ubuntu/test/ItChat/itchat/components/login.py", line 308, in sync_check
    if not isinstance(e.args[0].args[1], BadStatusLine):
IndexError: tuple index out of range

Traceback (most recent call last):
  File "/home/ubuntu/test/ItChat/itchat/components/login.py", line 248, in maintain_loop
    i = sync_check(self)
  File "/home/ubuntu/test/ItChat/itchat/components/login.py", line 308, in sync_check
    if not isinstance(e.args[0].args[1], BadStatusLine):
IndexError: tuple index out of range

Traceback (most recent call last):
  File "/home/ubuntu/test/ItChat/itchat/components/login.py", line 248, in maintain_loop
    i = sync_check(self)
  File "/home/ubuntu/test/ItChat/itchat/components/login.py", line 308, in sync_check
    if not isinstance(e.args[0].args[1], BadStatusLine):
IndexError: tuple index out of range

Traceback (most recent call last):
  File "/home/ubuntu/test/ItChat/itchat/components/login.py", line 248, in maintain_loop
    i = sync_check(self)
  File "/home/ubuntu/test/ItChat/itchat/components/login.py", line 308, in sync_check
    if not isinstance(e.args[0].args[1], BadStatusLine):
IndexError: tuple index out of range

Traceback (most recent call last):
  File "/home/ubuntu/test/ItChat/itchat/components/login.py", line 248, in maintain_loop
    i = sync_check(self)
  File "/home/ubuntu/test/ItChat/itchat/components/login.py", line 308, in sync_check
    if not isinstance(e.args[0].args[1], BadStatusLine):
IndexError: tuple index out of range

Traceback (most recent call last):
  File "/home/ubuntu/test/ItChat/itchat/components/login.py", line 248, in maintain_loop
    i = sync_check(self)
  File "/home/ubuntu/test/ItChat/itchat/components/login.py", line 308, in sync_check
    if not isinstance(e.args[0].args[1], BadStatusLine):
IndexError: tuple index out of range

Traceback (most recent call last):
  File "/home/ubuntu/test/ItChat/itchat/components/login.py", line 248, in maintain_loop
    i = sync_check(self)
  File "/home/ubuntu/test/ItChat/itchat/components/login.py", line 308, in sync_check
    if not isinstance(e.args[0].args[1], BadStatusLine):
IndexError: tuple index out of range

Traceback (most recent call last):
  File "/home/ubuntu/test/ItChat/itchat/components/login.py", line 248, in maintain_loop
    i = sync_check(self)
  File "/home/ubuntu/test/ItChat/itchat/components/login.py", line 308, in sync_check
    if not isinstance(e.args[0].args[1], BadStatusLine):
IndexError: tuple index out of range

Traceback (most recent call last):
  File "/home/ubuntu/test/ItChat/itchat/components/login.py", line 248, in maintain_loop
    i = sync_check(self)
  File "/home/ubuntu/test/ItChat/itchat/components/login.py", line 308, in sync_check
    if not isinstance(e.args[0].args[1], BadStatusLine):
IndexError: tuple index out of range

Traceback (most recent call last):
  File "/home/ubuntu/test/ItChat/itchat/components/login.py", line 248, in maintain_loop
    i = sync_check(self)
  File "/home/ubuntu/test/ItChat/itchat/components/login.py", line 308, in sync_check
    if not isinstance(e.args[0].args[1], BadStatusLine):
IndexError: tuple index out of range

Traceback (most recent call last):
  File "/home/ubuntu/test/ItChat/itchat/components/login.py", line 248, in maintain_loop
    i = sync_check(self)
  File "/home/ubuntu/test/ItChat/itchat/components/login.py", line 308, in sync_check
    if not isinstance(e.args[0].args[1], BadStatusLine):
IndexError: tuple index out of range

Traceback (most recent call last):
  File "/home/ubuntu/test/ItChat/itchat/components/login.py", line 248, in maintain_loop
    i = sync_check(self)
  File "/home/ubuntu/test/ItChat/itchat/components/login.py", line 308, in sync_check
    if not isinstance(e.args[0].args[1], BadStatusLine):
IndexError: tuple index out of range

Traceback (most recent call last):
  File "/home/ubuntu/test/ItChat/itchat/components/login.py", line 248, in maintain_loop
    i = sync_check(self)
  File "/home/ubuntu/test/ItChat/itchat/components/login.py", line 308, in sync_check
    if not isinstance(e.args[0].args[1], BadStatusLine):
IndexError: tuple index out of range

Traceback (most recent call last):
  File "/home/ubuntu/test/ItChat/itchat/components/login.py", line 248, in maintain_loop
    i = sync_check(self)
  File "/home/ubuntu/test/ItChat/itchat/components/login.py", line 308, in sync_check
    if not isinstance(e.args[0].args[1], BadStatusLine):
IndexError: tuple index out of range

Traceback (most recent call last):
  File "/home/ubuntu/test/ItChat/itchat/components/login.py", line 248, in maintain_loop
    i = sync_check(self)
  File "/home/ubuntu/test/ItChat/itchat/components/login.py", line 308, in sync_check
    if not isinstance(e.args[0].args[1], BadStatusLine):
IndexError: tuple index out of range

Traceback (most recent call last):
  File "/home/ubuntu/test/ItChat/itchat/components/login.py", line 248, in maintain_loop
    i = sync_check(self)
  File "/home/ubuntu/test/ItChat/itchat/components/login.py", line 308, in sync_check
    if not isinstance(e.args[0].args[1], BadStatusLine):
IndexError: tuple index out of range

Traceback (most recent call last):
  File "/home/ubuntu/test/ItChat/itchat/components/login.py", line 248, in maintain_loop
    i = sync_check(self)
  File "/home/ubuntu/test/ItChat/itchat/components/login.py", line 308, in sync_check
    if not isinstance(e.args[0].args[1], BadStatusLine):
IndexError: tuple index out of range

Traceback (most recent call last):
  File "/home/ubuntu/test/ItChat/itchat/components/login.py", line 248, in maintain_loop
    i = sync_check(self)
  File "/home/ubuntu/test/ItChat/itchat/components/login.py", line 308, in sync_check
    if not isinstance(e.args[0].args[1], BadStatusLine):
IndexError: tuple index out of range

Traceback (most recent call last):
  File "/home/ubuntu/test/ItChat/itchat/components/login.py", line 248, in maintain_loop
    i = sync_check(self)
  File "/home/ubuntu/test/ItChat/itchat/components/login.py", line 308, in sync_check
    if not isinstance(e.args[0].args[1], BadStatusLine):
IndexError: tuple index out of range

Traceback (most recent call last):
  File "/home/ubuntu/test/ItChat/itchat/components/login.py", line 248, in maintain_loop
    i = sync_check(self)
  File "/home/ubuntu/test/ItChat/itchat/components/login.py", line 308, in sync_check
    if not isinstance(e.args[0].args[1], BadStatusLine):
IndexError: tuple index out of range

Traceback (most recent call last):
  File "/home/ubuntu/test/ItChat/itchat/components/login.py", line 248, in maintain_loop
    i = sync_check(self)
  File "/home/ubuntu/test/ItChat/itchat/components/login.py", line 308, in sync_check
    if not isinstance(e.args[0].args[1], BadStatusLine):
IndexError: tuple index out of range

Traceback (most recent call last):
  File "/home/ubuntu/test/ItChat/itchat/components/login.py", line 248, in maintain_loop
    i = sync_check(self)
  File "/home/ubuntu/test/ItChat/itchat/components/login.py", line 308, in sync_check
    if not isinstance(e.args[0].args[1], BadStatusLine):
IndexError: tuple index out of range

Traceback (most recent call last):
  File "/home/ubuntu/test/ItChat/itchat/components/login.py", line 248, in maintain_loop
    i = sync_check(self)
  File "/home/ubuntu/test/ItChat/itchat/components/login.py", line 308, in sync_check
    if not isinstance(e.args[0].args[1], BadStatusLine):
IndexError: tuple index out of range

Traceback (most recent call last):
  File "/home/ubuntu/test/ItChat/itchat/components/login.py", line 248, in maintain_loop
    i = sync_check(self)
  File "/home/ubuntu/test/ItChat/itchat/components/login.py", line 308, in sync_check
    if not isinstance(e.args[0].args[1], BadStatusLine):
IndexError: tuple index out of range

Traceback (most recent call last):
  File "/home/ubuntu/test/ItChat/itchat/components/login.py", line 248, in maintain_loop
    i = sync_check(self)
  File "/home/ubuntu/test/ItChat/itchat/components/login.py", line 308, in sync_check
    if not isinstance(e.args[0].args[1], BadStatusLine):
IndexError: tuple index out of range

Traceback (most recent call last):
  File "/home/ubuntu/test/ItChat/itchat/components/login.py", line 248, in maintain_loop
    i = sync_check(self)
  File "/home/ubuntu/test/ItChat/itchat/components/login.py", line 308, in sync_check
    if not isinstance(e.args[0].args[1], BadStatusLine):
IndexError: tuple index out of range

Traceback (most recent call last):
  File "/home/ubuntu/test/ItChat/itchat/components/login.py", line 248, in maintain_loop
    i = sync_check(self)
  File "/home/ubuntu/test/ItChat/itchat/components/login.py", line 308, in sync_check
    if not isinstance(e.args[0].args[1], BadStatusLine):
IndexError: tuple index out of range

Traceback (most recent call last):
  File "/home/ubuntu/test/ItChat/itchat/components/login.py", line 248, in maintain_loop
    i = sync_check(self)
  File "/home/ubuntu/test/ItChat/itchat/components/login.py", line 308, in sync_check
    if not isinstance(e.args[0].args[1], BadStatusLine):
IndexError: tuple index out of range

Traceback (most recent call last):
  File "/home/ubuntu/test/ItChat/itchat/components/login.py", line 248, in maintain_loop
    i = sync_check(self)
  File "/home/ubuntu/test/ItChat/itchat/components/login.py", line 308, in sync_check
    if not isinstance(e.args[0].args[1], BadStatusLine):
IndexError: tuple index out of range

Traceback (most recent call last):
  File "/home/ubuntu/test/ItChat/itchat/components/login.py", line 254, in maintain_loop
    msgList, contactList = self.get_msg()
  File "/home/ubuntu/test/ItChat/itchat/components/login.py", line 336, in get_msg
    r = self.s.post(url, data=json.dumps(data), headers=headers, timeout=config.TIMEOUT)
  File "/home/ubuntu/.local/lib/python2.7/site-packages/requests/sessions.py", line 572, in post
    return self.request('POST', url, data=data, json=json, **kwargs)
  File "/home/ubuntu/.local/lib/python2.7/site-packages/requests/sessions.py", line 524, in request
    resp = self.send(prep, **send_kwargs)
  File "/home/ubuntu/.local/lib/python2.7/site-packages/requests/sessions.py", line 637, in send
    r = adapter.send(request, **kwargs)
  File "/home/ubuntu/.local/lib/python2.7/site-packages/requests/adapters.py", line 516, in send
    raise ConnectionError(e, request=request)
ConnectionError: HTTPSConnectionPool(host='wx.qq.com', port=443): Max retries exceeded with url: /cgi-bin/mmwebwx-bin/webwxsync?sid=DPBMWBFsFsy1cid7&skey=@crypt_9e7748df_5664f15bf3836bb0f012e20b5887ff99&pass_ticket=su28XLgcvMetzNMspEByIz0R08gBtPvRbYAiLaAc9TXs9rFtzaUbb1vgB4VHljmc (Caused by NewConnectionError('<urllib3.connection.VerifiedHTTPSConnection object at 0x7f90ada48dd0>: Failed to establish a new connection: [Errno -2] Name or service not known',))

Traceback (most recent call last):
  File "/home/ubuntu/test/ItChat/itchat/components/login.py", line 254, in maintain_loop
    msgList, contactList = self.get_msg()
  File "/home/ubuntu/test/ItChat/itchat/components/login.py", line 336, in get_msg
    r = self.s.post(url, data=json.dumps(data), headers=headers, timeout=config.TIMEOUT)
  File "/home/ubuntu/.local/lib/python2.7/site-packages/requests/sessions.py", line 572, in post
    return self.request('POST', url, data=data, json=json, **kwargs)
  File "/home/ubuntu/.local/lib/python2.7/site-packages/requests/sessions.py", line 524, in request
    resp = self.send(prep, **send_kwargs)
  File "/home/ubuntu/.local/lib/python2.7/site-packages/requests/sessions.py", line 637, in send
    r = adapter.send(request, **kwargs)
  File "/home/ubuntu/.local/lib/python2.7/site-packages/requests/adapters.py", line 516, in send
    raise ConnectionError(e, request=request)
ConnectionError: HTTPSConnectionPool(host='wx.qq.com', port=443): Max retries exceeded with url: /cgi-bin/mmwebwx-bin/webwxsync?sid=DPBMWBFsFsy1cid7&skey=@crypt_9e7748df_5664f15bf3836bb0f012e20b5887ff99&pass_ticket=su28XLgcvMetzNMspEByIz0R08gBtPvRbYAiLaAc9TXs9rFtzaUbb1vgB4VHljmc (Caused by NewConnectionError('<urllib3.connection.VerifiedHTTPSConnection object at 0x7f907cc86550>: Failed to establish a new connection: [Errno -2] Name or service not known',))

Traceback (most recent call last):
  File "/home/ubuntu/test/ItChat/itchat/components/login.py", line 254, in maintain_loop
    msgList, contactList = self.get_msg()
  File "/home/ubuntu/test/ItChat/itchat/components/login.py", line 336, in get_msg
    r = self.s.post(url, data=json.dumps(data), headers=headers, timeout=config.TIMEOUT)
  File "/home/ubuntu/.local/lib/python2.7/site-packages/requests/sessions.py", line 572, in post
    return self.request('POST', url, data=data, json=json, **kwargs)
  File "/home/ubuntu/.local/lib/python2.7/site-packages/requests/sessions.py", line 524, in request
    resp = self.send(prep, **send_kwargs)
  File "/home/ubuntu/.local/lib/python2.7/site-packages/requests/sessions.py", line 637, in send
    r = adapter.send(request, **kwargs)
  File "/home/ubuntu/.local/lib/python2.7/site-packages/requests/adapters.py", line 516, in send
    raise ConnectionError(e, request=request)
ConnectionError: HTTPSConnectionPool(host='wx.qq.com', port=443): Max retries exceeded with url: /cgi-bin/mmwebwx-bin/webwxsync?sid=DPBMWBFsFsy1cid7&skey=@crypt_9e7748df_5664f15bf3836bb0f012e20b5887ff99&pass_ticket=su28XLgcvMetzNMspEByIz0R08gBtPvRbYAiLaAc9TXs9rFtzaUbb1vgB4VHljmc (Caused by NewConnectionError('<urllib3.connection.VerifiedHTTPSConnection object at 0x7f90837eae90>: Failed to establish a new connection: [Errno -2] Name or service not known',))

Traceback (most recent call last):
  File "/home/ubuntu/test/ItChat/itchat/components/login.py", line 254, in maintain_loop
    msgList, contactList = self.get_msg()
  File "/home/ubuntu/test/ItChat/itchat/components/login.py", line 336, in get_msg
    r = self.s.post(url, data=json.dumps(data), headers=headers, timeout=config.TIMEOUT)
  File "/home/ubuntu/.local/lib/python2.7/site-packages/requests/sessions.py", line 572, in post
    return self.request('POST', url, data=data, json=json, **kwargs)
  File "/home/ubuntu/.local/lib/python2.7/site-packages/requests/sessions.py", line 524, in request
    resp = self.send(prep, **send_kwargs)
  File "/home/ubuntu/.local/lib/python2.7/site-packages/requests/sessions.py", line 637, in send
    r = adapter.send(request, **kwargs)
  File "/home/ubuntu/.local/lib/python2.7/site-packages/requests/adapters.py", line 516, in send
    raise ConnectionError(e, request=request)
ConnectionError: HTTPSConnectionPool(host='wx.qq.com', port=443): Max retries exceeded with url: /cgi-bin/mmwebwx-bin/webwxsync?sid=DPBMWBFsFsy1cid7&skey=@crypt_9e7748df_5664f15bf3836bb0f012e20b5887ff99&pass_ticket=su28XLgcvMetzNMspEByIz0R08gBtPvRbYAiLaAc9TXs9rFtzaUbb1vgB4VHljmc (Caused by NewConnectionError('<urllib3.connection.VerifiedHTTPSConnection object at 0x7f9083b68f50>: Failed to establish a new connection: [Errno -2] Name or service not known',))

Traceback (most recent call last):
  File "/home/ubuntu/test/ItChat/itchat/components/login.py", line 254, in maintain_loop
    msgList, contactList = self.get_msg()
  File "/home/ubuntu/test/ItChat/itchat/components/login.py", line 336, in get_msg
    r = self.s.post(url, data=json.dumps(data), headers=headers, timeout=config.TIMEOUT)
  File "/home/ubuntu/.local/lib/python2.7/site-packages/requests/sessions.py", line 572, in post
    return self.request('POST', url, data=data, json=json, **kwargs)
  File "/home/ubuntu/.local/lib/python2.7/site-packages/requests/sessions.py", line 524, in request
    resp = self.send(prep, **send_kwargs)
  File "/home/ubuntu/.local/lib/python2.7/site-packages/requests/sessions.py", line 637, in send
    r = adapter.send(request, **kwargs)
  File "/home/ubuntu/.local/lib/python2.7/site-packages/requests/adapters.py", line 516, in send
    raise ConnectionError(e, request=request)
ConnectionError: HTTPSConnectionPool(host='wx.qq.com', port=443): Max retries exceeded with url: /cgi-bin/mmwebwx-bin/webwxsync?sid=DPBMWBFsFsy1cid7&skey=@crypt_9e7748df_5664f15bf3836bb0f012e20b5887ff99&pass_ticket=su28XLgcvMetzNMspEByIz0R08gBtPvRbYAiLaAc9TXs9rFtzaUbb1vgB4VHljmc (Caused by NewConnectionError('<urllib3.connection.VerifiedHTTPSConnection object at 0x7f90b5939710>: Failed to establish a new connection: [Errno -2] Name or service not known',))

Traceback (most recent call last):
  File "/home/ubuntu/test/ItChat/itchat/components/login.py", line 254, in maintain_loop
    msgList, contactList = self.get_msg()
  File "/home/ubuntu/test/ItChat/itchat/components/login.py", line 336, in get_msg
    r = self.s.post(url, data=json.dumps(data), headers=headers, timeout=config.TIMEOUT)
  File "/home/ubuntu/.local/lib/python2.7/site-packages/requests/sessions.py", line 572, in post
    return self.request('POST', url, data=data, json=json, **kwargs)
  File "/home/ubuntu/.local/lib/python2.7/site-packages/requests/sessions.py", line 524, in request
    resp = self.send(prep, **send_kwargs)
  File "/home/ubuntu/.local/lib/python2.7/site-packages/requests/sessions.py", line 637, in send
    r = adapter.send(request, **kwargs)
  File "/home/ubuntu/.local/lib/python2.7/site-packages/requests/adapters.py", line 516, in send
    raise ConnectionError(e, request=request)
ConnectionError: HTTPSConnectionPool(host='wx.qq.com', port=443): Max retries exceeded with url: /cgi-bin/mmwebwx-bin/webwxsync?sid=DPBMWBFsFsy1cid7&skey=@crypt_9e7748df_5664f15bf3836bb0f012e20b5887ff99&pass_ticket=su28XLgcvMetzNMspEByIz0R08gBtPvRbYAiLaAc9TXs9rFtzaUbb1vgB4VHljmc (Caused by NewConnectionError('<urllib3.connection.VerifiedHTTPSConnection object at 0x7f90b42872d0>: Failed to establish a new connection: [Errno -2] Name or service not known',))

Traceback (most recent call last):
  File "/home/ubuntu/test/ItChat/itchat/components/login.py", line 254, in maintain_loop
    msgList, contactList = self.get_msg()
  File "/home/ubuntu/test/ItChat/itchat/components/login.py", line 336, in get_msg
    r = self.s.post(url, data=json.dumps(data), headers=headers, timeout=config.TIMEOUT)
  File "/home/ubuntu/.local/lib/python2.7/site-packages/requests/sessions.py", line 572, in post
    return self.request('POST', url, data=data, json=json, **kwargs)
  File "/home/ubuntu/.local/lib/python2.7/site-packages/requests/sessions.py", line 524, in request
    resp = self.send(prep, **send_kwargs)
  File "/home/ubuntu/.local/lib/python2.7/site-packages/requests/sessions.py", line 637, in send
    r = adapter.send(request, **kwargs)
  File "/home/ubuntu/.local/lib/python2.7/site-packages/requests/adapters.py", line 516, in send
    raise ConnectionError(e, request=request)
ConnectionError: HTTPSConnectionPool(host='wx.qq.com', port=443): Max retries exceeded with url: /cgi-bin/mmwebwx-bin/webwxsync?sid=DPBMWBFsFsy1cid7&skey=@crypt_9e7748df_5664f15bf3836bb0f012e20b5887ff99&pass_ticket=su28XLgcvMetzNMspEByIz0R08gBtPvRbYAiLaAc9TXs9rFtzaUbb1vgB4VHljmc (Caused by NewConnectionError('<urllib3.connection.VerifiedHTTPSConnection object at 0x7f90b55b6b50>: Failed to establish a new connection: [Errno -2] Name or service not known',))

Traceback (most recent call last):
  File "/home/ubuntu/test/ItChat/itchat/components/login.py", line 254, in maintain_loop
    msgList, contactList = self.get_msg()
  File "/home/ubuntu/test/ItChat/itchat/components/login.py", line 336, in get_msg
    r = self.s.post(url, data=json.dumps(data), headers=headers, timeout=config.TIMEOUT)
  File "/home/ubuntu/.local/lib/python2.7/site-packages/requests/sessions.py", line 572, in post
    return self.request('POST', url, data=data, json=json, **kwargs)
  File "/home/ubuntu/.local/lib/python2.7/site-packages/requests/sessions.py", line 524, in request
    resp = self.send(prep, **send_kwargs)
  File "/home/ubuntu/.local/lib/python2.7/site-packages/requests/sessions.py", line 637, in send
    r = adapter.send(request, **kwargs)
  File "/home/ubuntu/.local/lib/python2.7/site-packages/requests/adapters.py", line 516, in send
    raise ConnectionError(e, request=request)
ConnectionError: HTTPSConnectionPool(host='wx.qq.com', port=443): Max retries exceeded with url: /cgi-bin/mmwebwx-bin/webwxsync?sid=DPBMWBFsFsy1cid7&skey=@crypt_9e7748df_5664f15bf3836bb0f012e20b5887ff99&pass_ticket=su28XLgcvMetzNMspEByIz0R08gBtPvRbYAiLaAc9TXs9rFtzaUbb1vgB4VHljmc (Caused by NewConnectionError('<urllib3.connection.VerifiedHTTPSConnection object at 0x7f906bf39f90>: Failed to establish a new connection: [Errno -2] Name or service not known',))

Traceback (most recent call last):
  File "/home/ubuntu/test/ItChat/itchat/components/login.py", line 254, in maintain_loop
    msgList, contactList = self.get_msg()
  File "/home/ubuntu/test/ItChat/itchat/components/login.py", line 336, in get_msg
    r = self.s.post(url, data=json.dumps(data), headers=headers, timeout=config.TIMEOUT)
  File "/home/ubuntu/.local/lib/python2.7/site-packages/requests/sessions.py", line 572, in post
    return self.request('POST', url, data=data, json=json, **kwargs)
  File "/home/ubuntu/.local/lib/python2.7/site-packages/requests/sessions.py", line 524, in request
    resp = self.send(prep, **send_kwargs)
  File "/home/ubuntu/.local/lib/python2.7/site-packages/requests/sessions.py", line 637, in send
    r = adapter.send(request, **kwargs)
  File "/home/ubuntu/.local/lib/python2.7/site-packages/requests/adapters.py", line 516, in send
    raise ConnectionError(e, request=request)
ConnectionError: HTTPSConnectionPool(host='wx.qq.com', port=443): Max retries exceeded with url: /cgi-bin/mmwebwx-bin/webwxsync?sid=DPBMWBFsFsy1cid7&skey=@crypt_9e7748df_5664f15bf3836bb0f012e20b5887ff99&pass_ticket=su28XLgcvMetzNMspEByIz0R08gBtPvRbYAiLaAc9TXs9rFtzaUbb1vgB4VHljmc (Caused by NewConnectionError('<urllib3.connection.VerifiedHTTPSConnection object at 0x7f909d663e10>: Failed to establish a new connection: [Errno -2] Name or service not known',))

Traceback (most recent call last):
  File "/home/ubuntu/test/ItChat/itchat/components/login.py", line 254, in maintain_loop
    msgList, contactList = self.get_msg()
  File "/home/ubuntu/test/ItChat/itchat/components/login.py", line 336, in get_msg
    r = self.s.post(url, data=json.dumps(data), headers=headers, timeout=config.TIMEOUT)
  File "/home/ubuntu/.local/lib/python2.7/site-packages/requests/sessions.py", line 572, in post
    return self.request('POST', url, data=data, json=json, **kwargs)
  File "/home/ubuntu/.local/lib/python2.7/site-packages/requests/sessions.py", line 524, in request
    resp = self.send(prep, **send_kwargs)
  File "/home/ubuntu/.local/lib/python2.7/site-packages/requests/sessions.py", line 637, in send
    r = adapter.send(request, **kwargs)
  File "/home/ubuntu/.local/lib/python2.7/site-packages/requests/adapters.py", line 516, in send
    raise ConnectionError(e, request=request)
ConnectionError: HTTPSConnectionPool(host='wx.qq.com', port=443): Max retries exceeded with url: /cgi-bin/mmwebwx-bin/webwxsync?sid=DPBMWBFsFsy1cid7&skey=@crypt_9e7748df_5664f15bf3836bb0f012e20b5887ff99&pass_ticket=su28XLgcvMetzNMspEByIz0R08gBtPvRbYAiLaAc9TXs9rFtzaUbb1vgB4VHljmc (Caused by NewConnectionError('<urllib3.connection.VerifiedHTTPSConnection object at 0x7f90838ffed0>: Failed to establish a new connection: [Errno -2] Name or service not known',))

Traceback (most recent call last):
  File "/home/ubuntu/test/ItChat/itchat/components/login.py", line 254, in maintain_loop
    msgList, contactList = self.get_msg()
  File "/home/ubuntu/test/ItChat/itchat/components/login.py", line 336, in get_msg
    r = self.s.post(url, data=json.dumps(data), headers=headers, timeout=config.TIMEOUT)
  File "/home/ubuntu/.local/lib/python2.7/site-packages/requests/sessions.py", line 572, in post
    return self.request('POST', url, data=data, json=json, **kwargs)
  File "/home/ubuntu/.local/lib/python2.7/site-packages/requests/sessions.py", line 524, in request
    resp = self.send(prep, **send_kwargs)
  File "/home/ubuntu/.local/lib/python2.7/site-packages/requests/sessions.py", line 637, in send
    r = adapter.send(request, **kwargs)
  File "/home/ubuntu/.local/lib/python2.7/site-packages/requests/adapters.py", line 516, in send
    raise ConnectionError(e, request=request)
ConnectionError: HTTPSConnectionPool(host='wx.qq.com', port=443): Max retries exceeded with url: /cgi-bin/mmwebwx-bin/webwxsync?sid=DPBMWBFsFsy1cid7&skey=@crypt_9e7748df_5664f15bf3836bb0f012e20b5887ff99&pass_ticket=su28XLgcvMetzNMspEByIz0R08gBtPvRbYAiLaAc9TXs9rFtzaUbb1vgB4VHljmc (Caused by NewConnectionError('<urllib3.connection.VerifiedHTTPSConnection object at 0x7f906bf39190>: Failed to establish a new connection: [Errno -2] Name or service not known',))

Traceback (most recent call last):
  File "/home/ubuntu/test/ItChat/itchat/components/login.py", line 254, in maintain_loop
    msgList, contactList = self.get_msg()
  File "/home/ubuntu/test/ItChat/itchat/components/login.py", line 336, in get_msg
    r = self.s.post(url, data=json.dumps(data), headers=headers, timeout=config.TIMEOUT)
  File "/home/ubuntu/.local/lib/python2.7/site-packages/requests/sessions.py", line 572, in post
    return self.request('POST', url, data=data, json=json, **kwargs)
  File "/home/ubuntu/.local/lib/python2.7/site-packages/requests/sessions.py", line 524, in request
    resp = self.send(prep, **send_kwargs)
  File "/home/ubuntu/.local/lib/python2.7/site-packages/requests/sessions.py", line 637, in send
    r = adapter.send(request, **kwargs)
  File "/home/ubuntu/.local/lib/python2.7/site-packages/requests/adapters.py", line 516, in send
    raise ConnectionError(e, request=request)
ConnectionError: HTTPSConnectionPool(host='wx.qq.com', port=443): Max retries exceeded with url: /cgi-bin/mmwebwx-bin/webwxsync?sid=DPBMWBFsFsy1cid7&skey=@crypt_9e7748df_5664f15bf3836bb0f012e20b5887ff99&pass_ticket=su28XLgcvMetzNMspEByIz0R08gBtPvRbYAiLaAc9TXs9rFtzaUbb1vgB4VHljmc (Caused by NewConnectionError('<urllib3.connection.VerifiedHTTPSConnection object at 0x7f90b412d390>: Failed to establish a new connection: [Errno -2] Name or service not known',))

Traceback (most recent call last):
  File "/home/ubuntu/test/ItChat/itchat/components/login.py", line 254, in maintain_loop
    msgList, contactList = self.get_msg()
  File "/home/ubuntu/test/ItChat/itchat/components/login.py", line 336, in get_msg
    r = self.s.post(url, data=json.dumps(data), headers=headers, timeout=config.TIMEOUT)
  File "/home/ubuntu/.local/lib/python2.7/site-packages/requests/sessions.py", line 572, in post
    return self.request('POST', url, data=data, json=json, **kwargs)
  File "/home/ubuntu/.local/lib/python2.7/site-packages/requests/sessions.py", line 524, in request
    resp = self.send(prep, **send_kwargs)
  File "/home/ubuntu/.local/lib/python2.7/site-packages/requests/sessions.py", line 637, in send
    r = adapter.send(request, **kwargs)
  File "/home/ubuntu/.local/lib/python2.7/site-packages/requests/adapters.py", line 516, in send
    raise ConnectionError(e, request=request)
ConnectionError: HTTPSConnectionPool(host='wx.qq.com', port=443): Max retries exceeded with url: /cgi-bin/mmwebwx-bin/webwxsync?sid=DPBMWBFsFsy1cid7&skey=@crypt_9e7748df_5664f15bf3836bb0f012e20b5887ff99&pass_ticket=su28XLgcvMetzNMspEByIz0R08gBtPvRbYAiLaAc9TXs9rFtzaUbb1vgB4VHljmc (Caused by NewConnectionError('<urllib3.connection.VerifiedHTTPSConnection object at 0x7f9078593990>: Failed to establish a new connection: [Errno -2] Name or service not known',))

Traceback (most recent call last):
  File "/home/ubuntu/test/ItChat/itchat/components/login.py", line 254, in maintain_loop
    msgList, contactList = self.get_msg()
  File "/home/ubuntu/test/ItChat/itchat/components/login.py", line 336, in get_msg
    r = self.s.post(url, data=json.dumps(data), headers=headers, timeout=config.TIMEOUT)
  File "/home/ubuntu/.local/lib/python2.7/site-packages/requests/sessions.py", line 572, in post
    return self.request('POST', url, data=data, json=json, **kwargs)
  File "/home/ubuntu/.local/lib/python2.7/site-packages/requests/sessions.py", line 524, in request
    resp = self.send(prep, **send_kwargs)
  File "/home/ubuntu/.local/lib/python2.7/site-packages/requests/sessions.py", line 637, in send
    r = adapter.send(request, **kwargs)
  File "/home/ubuntu/.local/lib/python2.7/site-packages/requests/adapters.py", line 516, in send
    raise ConnectionError(e, request=request)
ConnectionError: HTTPSConnectionPool(host='wx.qq.com', port=443): Max retries exceeded with url: /cgi-bin/mmwebwx-bin/webwxsync?sid=DPBMWBFsFsy1cid7&skey=@crypt_9e7748df_5664f15bf3836bb0f012e20b5887ff99&pass_ticket=su28XLgcvMetzNMspEByIz0R08gBtPvRbYAiLaAc9TXs9rFtzaUbb1vgB4VHljmc (Caused by NewConnectionError('<urllib3.connection.VerifiedHTTPSConnection object at 0x7f90745c2050>: Failed to establish a new connection: [Errno -2] Name or service not known',))

Traceback (most recent call last):
  File "/home/ubuntu/test/ItChat/itchat/components/login.py", line 254, in maintain_loop
    msgList, contactList = self.get_msg()
  File "/home/ubuntu/test/ItChat/itchat/components/login.py", line 336, in get_msg
    r = self.s.post(url, data=json.dumps(data), headers=headers, timeout=config.TIMEOUT)
  File "/home/ubuntu/.local/lib/python2.7/site-packages/requests/sessions.py", line 572, in post
    return self.request('POST', url, data=data, json=json, **kwargs)
  File "/home/ubuntu/.local/lib/python2.7/site-packages/requests/sessions.py", line 524, in request
    resp = self.send(prep, **send_kwargs)
  File "/home/ubuntu/.local/lib/python2.7/site-packages/requests/sessions.py", line 637, in send
    r = adapter.send(request, **kwargs)
  File "/home/ubuntu/.local/lib/python2.7/site-packages/requests/adapters.py", line 516, in send
    raise ConnectionError(e, request=request)
ConnectionError: HTTPSConnectionPool(host='wx.qq.com', port=443): Max retries exceeded with url: /cgi-bin/mmwebwx-bin/webwxsync?sid=DPBMWBFsFsy1cid7&skey=@crypt_9e7748df_5664f15bf3836bb0f012e20b5887ff99&pass_ticket=su28XLgcvMetzNMspEByIz0R08gBtPvRbYAiLaAc9TXs9rFtzaUbb1vgB4VHljmc (Caused by NewConnectionError('<urllib3.connection.VerifiedHTTPSConnection object at 0x7f906c48fa90>: Failed to establish a new connection: [Errno -2] Name or service not known',))

Traceback (most recent call last):
  File "/home/ubuntu/test/ItChat/itchat/components/login.py", line 254, in maintain_loop
    msgList, contactList = self.get_msg()
  File "/home/ubuntu/test/ItChat/itchat/components/login.py", line 336, in get_msg
    r = self.s.post(url, data=json.dumps(data), headers=headers, timeout=config.TIMEOUT)
  File "/home/ubuntu/.local/lib/python2.7/site-packages/requests/sessions.py", line 572, in post
    return self.request('POST', url, data=data, json=json, **kwargs)
  File "/home/ubuntu/.local/lib/python2.7/site-packages/requests/sessions.py", line 524, in request
    resp = self.send(prep, **send_kwargs)
  File "/home/ubuntu/.local/lib/python2.7/site-packages/requests/sessions.py", line 637, in send
    r = adapter.send(request, **kwargs)
  File "/home/ubuntu/.local/lib/python2.7/site-packages/requests/adapters.py", line 516, in send
    raise ConnectionError(e, request=request)
ConnectionError: HTTPSConnectionPool(host='wx.qq.com', port=443): Max retries exceeded with url: /cgi-bin/mmwebwx-bin/webwxsync?sid=DPBMWBFsFsy1cid7&skey=@crypt_9e7748df_5664f15bf3836bb0f012e20b5887ff99&pass_ticket=su28XLgcvMetzNMspEByIz0R08gBtPvRbYAiLaAc9TXs9rFtzaUbb1vgB4VHljmc (Caused by NewConnectionError('<urllib3.connection.VerifiedHTTPSConnection object at 0x7f907ce4c410>: Failed to establish a new connection: [Errno -2] Name or service not known',))

Traceback (most recent call last):
  File "/home/ubuntu/test/ItChat/itchat/components/login.py", line 254, in maintain_loop
    msgList, contactList = self.get_msg()
  File "/home/ubuntu/test/ItChat/itchat/components/login.py", line 336, in get_msg
    r = self.s.post(url, data=json.dumps(data), headers=headers, timeout=config.TIMEOUT)
  File "/home/ubuntu/.local/lib/python2.7/site-packages/requests/sessions.py", line 572, in post
    return self.request('POST', url, data=data, json=json, **kwargs)
  File "/home/ubuntu/.local/lib/python2.7/site-packages/requests/sessions.py", line 524, in request
    resp = self.send(prep, **send_kwargs)
  File "/home/ubuntu/.local/lib/python2.7/site-packages/requests/sessions.py", line 637, in send
    r = adapter.send(request, **kwargs)
  File "/home/ubuntu/.local/lib/python2.7/site-packages/requests/adapters.py", line 516, in send
    raise ConnectionError(e, request=request)
ConnectionError: HTTPSConnectionPool(host='wx.qq.com', port=443): Max retries exceeded with url: /cgi-bin/mmwebwx-bin/webwxsync?sid=DPBMWBFsFsy1cid7&skey=@crypt_9e7748df_5664f15bf3836bb0f012e20b5887ff99&pass_ticket=su28XLgcvMetzNMspEByIz0R08gBtPvRbYAiLaAc9TXs9rFtzaUbb1vgB4VHljmc (Caused by NewConnectionError('<urllib3.connection.VerifiedHTTPSConnection object at 0x7f907d2d6610>: Failed to establish a new connection: [Errno -2] Name or service not known',))

Traceback (most recent call last):
  File "/home/ubuntu/test/ItChat/itchat/components/login.py", line 254, in maintain_loop
    msgList, contactList = self.get_msg()
  File "/home/ubuntu/test/ItChat/itchat/components/login.py", line 336, in get_msg
    r = self.s.post(url, data=json.dumps(data), headers=headers, timeout=config.TIMEOUT)
  File "/home/ubuntu/.local/lib/python2.7/site-packages/requests/sessions.py", line 572, in post
    return self.request('POST', url, data=data, json=json, **kwargs)
  File "/home/ubuntu/.local/lib/python2.7/site-packages/requests/sessions.py", line 524, in request
    resp = self.send(prep, **send_kwargs)
  File "/home/ubuntu/.local/lib/python2.7/site-packages/requests/sessions.py", line 637, in send
    r = adapter.send(request, **kwargs)
  File "/home/ubuntu/.local/lib/python2.7/site-packages/requests/adapters.py", line 516, in send
    raise ConnectionError(e, request=request)
ConnectionError: HTTPSConnectionPool(host='wx.qq.com', port=443): Max retries exceeded with url: /cgi-bin/mmwebwx-bin/webwxsync?sid=DPBMWBFsFsy1cid7&skey=@crypt_9e7748df_5664f15bf3836bb0f012e20b5887ff99&pass_ticket=su28XLgcvMetzNMspEByIz0R08gBtPvRbYAiLaAc9TXs9rFtzaUbb1vgB4VHljmc (Caused by NewConnectionError('<urllib3.connection.VerifiedHTTPSConnection object at 0x7f907ce4cb10>: Failed to establish a new connection: [Errno -2] Name or service not known',))

Traceback (most recent call last):
  File "/home/ubuntu/test/ItChat/itchat/components/login.py", line 254, in maintain_loop
    msgList, contactList = self.get_msg()
  File "/home/ubuntu/test/ItChat/itchat/components/login.py", line 336, in get_msg
    r = self.s.post(url, data=json.dumps(data), headers=headers, timeout=config.TIMEOUT)
  File "/home/ubuntu/.local/lib/python2.7/site-packages/requests/sessions.py", line 572, in post
    return self.request('POST', url, data=data, json=json, **kwargs)
  File "/home/ubuntu/.local/lib/python2.7/site-packages/requests/sessions.py", line 524, in request
    resp = self.send(prep, **send_kwargs)
  File "/home/ubuntu/.local/lib/python2.7/site-packages/requests/sessions.py", line 637, in send
    r = adapter.send(request, **kwargs)
  File "/home/ubuntu/.local/lib/python2.7/site-packages/requests/adapters.py", line 516, in send
    raise ConnectionError(e, request=request)
ConnectionError: HTTPSConnectionPool(host='wx.qq.com', port=443): Max retries exceeded with url: /cgi-bin/mmwebwx-bin/webwxsync?sid=DPBMWBFsFsy1cid7&skey=@crypt_9e7748df_5664f15bf3836bb0f012e20b5887ff99&pass_ticket=su28XLgcvMetzNMspEByIz0R08gBtPvRbYAiLaAc9TXs9rFtzaUbb1vgB4VHljmc (Caused by NewConnectionError('<urllib3.connection.VerifiedHTTPSConnection object at 0x7f909d6304d0>: Failed to establish a new connection: [Errno -2] Name or service not known',))

Traceback (most recent call last):
  File "/home/ubuntu/test/ItChat/itchat/components/login.py", line 254, in maintain_loop
    msgList, contactList = self.get_msg()
  File "/home/ubuntu/test/ItChat/itchat/components/login.py", line 336, in get_msg
    r = self.s.post(url, data=json.dumps(data), headers=headers, timeout=config.TIMEOUT)
  File "/home/ubuntu/.local/lib/python2.7/site-packages/requests/sessions.py", line 572, in post
    return self.request('POST', url, data=data, json=json, **kwargs)
  File "/home/ubuntu/.local/lib/python2.7/site-packages/requests/sessions.py", line 524, in request
    resp = self.send(prep, **send_kwargs)
  File "/home/ubuntu/.local/lib/python2.7/site-packages/requests/sessions.py", line 637, in send
    r = adapter.send(request, **kwargs)
  File "/home/ubuntu/.local/lib/python2.7/site-packages/requests/adapters.py", line 516, in send
    raise ConnectionError(e, request=request)
ConnectionError: HTTPSConnectionPool(host='wx.qq.com', port=443): Max retries exceeded with url: /cgi-bin/mmwebwx-bin/webwxsync?sid=DPBMWBFsFsy1cid7&skey=@crypt_9e7748df_5664f15bf3836bb0f012e20b5887ff99&pass_ticket=su28XLgcvMetzNMspEByIz0R08gBtPvRbYAiLaAc9TXs9rFtzaUbb1vgB4VHljmc (Caused by NewConnectionError('<urllib3.connection.VerifiedHTTPSConnection object at 0x7f907a54c110>: Failed to establish a new connection: [Errno -2] Name or service not known',))

Traceback (most recent call last):
  File "/home/ubuntu/test/ItChat/itchat/components/login.py", line 254, in maintain_loop
    msgList, contactList = self.get_msg()
  File "/home/ubuntu/test/ItChat/itchat/components/login.py", line 336, in get_msg
    r = self.s.post(url, data=json.dumps(data), headers=headers, timeout=config.TIMEOUT)
  File "/home/ubuntu/.local/lib/python2.7/site-packages/requests/sessions.py", line 572, in post
    return self.request('POST', url, data=data, json=json, **kwargs)
  File "/home/ubuntu/.local/lib/python2.7/site-packages/requests/sessions.py", line 524, in request
    resp = self.send(prep, **send_kwargs)
  File "/home/ubuntu/.local/lib/python2.7/site-packages/requests/sessions.py", line 637, in send
    r = adapter.send(request, **kwargs)
  File "/home/ubuntu/.local/lib/python2.7/site-packages/requests/adapters.py", line 516, in send
    raise ConnectionError(e, request=request)
ConnectionError: HTTPSConnectionPool(host='wx.qq.com', port=443): Max retries exceeded with url: /cgi-bin/mmwebwx-bin/webwxsync?sid=DPBMWBFsFsy1cid7&skey=@crypt_9e7748df_5664f15bf3836bb0f012e20b5887ff99&pass_ticket=su28XLgcvMetzNMspEByIz0R08gBtPvRbYAiLaAc9TXs9rFtzaUbb1vgB4VHljmc (Caused by NewConnectionError('<urllib3.connection.VerifiedHTTPSConnection object at 0x7f909d663310>: Failed to establish a new connection: [Errno -2] Name or service not known',))

Traceback (most recent call last):
  File "/home/ubuntu/test/ItChat/itchat/components/login.py", line 254, in maintain_loop
    msgList, contactList = self.get_msg()
  File "/home/ubuntu/test/ItChat/itchat/components/login.py", line 336, in get_msg
    r = self.s.post(url, data=json.dumps(data), headers=headers, timeout=config.TIMEOUT)
  File "/home/ubuntu/.local/lib/python2.7/site-packages/requests/sessions.py", line 572, in post
    return self.request('POST', url, data=data, json=json, **kwargs)
  File "/home/ubuntu/.local/lib/python2.7/site-packages/requests/sessions.py", line 524, in request
    resp = self.send(prep, **send_kwargs)
  File "/home/ubuntu/.local/lib/python2.7/site-packages/requests/sessions.py", line 637, in send
    r = adapter.send(request, **kwargs)
  File "/home/ubuntu/.local/lib/python2.7/site-packages/requests/adapters.py", line 516, in send
    raise ConnectionError(e, request=request)
ConnectionError: HTTPSConnectionPool(host='wx.qq.com', port=443): Max retries exceeded with url: /cgi-bin/mmwebwx-bin/webwxsync?sid=DPBMWBFsFsy1cid7&skey=@crypt_9e7748df_5664f15bf3836bb0f012e20b5887ff99&pass_ticket=su28XLgcvMetzNMspEByIz0R08gBtPvRbYAiLaAc9TXs9rFtzaUbb1vgB4VHljmc (Caused by NewConnectionError('<urllib3.connection.VerifiedHTTPSConnection object at 0x7f906c48f750>: Failed to establish a new connection: [Errno -2] Name or service not known',))

Traceback (most recent call last):
  File "/home/ubuntu/test/ItChat/itchat/components/login.py", line 254, in maintain_loop
    msgList, contactList = self.get_msg()
  File "/home/ubuntu/test/ItChat/itchat/components/login.py", line 336, in get_msg
    r = self.s.post(url, data=json.dumps(data), headers=headers, timeout=config.TIMEOUT)
  File "/home/ubuntu/.local/lib/python2.7/site-packages/requests/sessions.py", line 572, in post
    return self.request('POST', url, data=data, json=json, **kwargs)
  File "/home/ubuntu/.local/lib/python2.7/site-packages/requests/sessions.py", line 524, in request
    resp = self.send(prep, **send_kwargs)
  File "/home/ubuntu/.local/lib/python2.7/site-packages/requests/sessions.py", line 637, in send
    r = adapter.send(request, **kwargs)
  File "/home/ubuntu/.local/lib/python2.7/site-packages/requests/adapters.py", line 516, in send
    raise ConnectionError(e, request=request)
ConnectionError: HTTPSConnectionPool(host='wx.qq.com', port=443): Max retries exceeded with url: /cgi-bin/mmwebwx-bin/webwxsync?sid=DPBMWBFsFsy1cid7&skey=@crypt_9e7748df_5664f15bf3836bb0f012e20b5887ff99&pass_ticket=su28XLgcvMetzNMspEByIz0R08gBtPvRbYAiLaAc9TXs9rFtzaUbb1vgB4VHljmc (Caused by NewConnectionError('<urllib3.connection.VerifiedHTTPSConnection object at 0x7f907cc1fb10>: Failed to establish a new connection: [Errno -2] Name or service not known',))

Traceback (most recent call last):
  File "/home/ubuntu/test/ItChat/itchat/components/login.py", line 248, in maintain_loop
    i = sync_check(self)
  File "/home/ubuntu/test/ItChat/itchat/components/login.py", line 308, in sync_check
    if not isinstance(e.args[0].args[1], BadStatusLine):
IndexError: tuple index out of range

Traceback (most recent call last):
  File "/home/ubuntu/test/ItChat/itchat/components/login.py", line 248, in maintain_loop
    i = sync_check(self)
  File "/home/ubuntu/test/ItChat/itchat/components/login.py", line 308, in sync_check
    if not isinstance(e.args[0].args[1], BadStatusLine):
IndexError: tuple index out of range

Traceback (most recent call last):
  File "/home/ubuntu/test/ItChat/itchat/components/login.py", line 248, in maintain_loop
    i = sync_check(self)
  File "/home/ubuntu/test/ItChat/itchat/components/login.py", line 308, in sync_check
    if not isinstance(e.args[0].args[1], BadStatusLine):
IndexError: tuple index out of range

Traceback (most recent call last):
  File "/home/ubuntu/test/ItChat/itchat/components/login.py", line 248, in maintain_loop
    i = sync_check(self)
  File "/home/ubuntu/test/ItChat/itchat/components/login.py", line 308, in sync_check
    if not isinstance(e.args[0].args[1], BadStatusLine):
IndexError: tuple index out of range

Traceback (most recent call last):
  File "/home/ubuntu/test/ItChat/itchat/components/login.py", line 248, in maintain_loop
    i = sync_check(self)
  File "/home/ubuntu/test/ItChat/itchat/components/login.py", line 308, in sync_check
    if not isinstance(e.args[0].args[1], BadStatusLine):
IndexError: tuple index out of range

Traceback (most recent call last):
  File "/home/ubuntu/test/ItChat/itchat/components/login.py", line 254, in maintain_loop
    msgList, contactList = self.get_msg()
  File "/home/ubuntu/test/ItChat/itchat/components/login.py", line 336, in get_msg
    r = self.s.post(url, data=json.dumps(data), headers=headers, timeout=config.TIMEOUT)
  File "/home/ubuntu/.local/lib/python2.7/site-packages/requests/sessions.py", line 572, in post
    return self.request('POST', url, data=data, json=json, **kwargs)
  File "/home/ubuntu/.local/lib/python2.7/site-packages/requests/sessions.py", line 524, in request
    resp = self.send(prep, **send_kwargs)
  File "/home/ubuntu/.local/lib/python2.7/site-packages/requests/sessions.py", line 637, in send
    r = adapter.send(request, **kwargs)
  File "/home/ubuntu/.local/lib/python2.7/site-packages/requests/adapters.py", line 516, in send
    raise ConnectionError(e, request=request)
ConnectionError: HTTPSConnectionPool(host='wx.qq.com', port=443): Max retries exceeded with url: /cgi-bin/mmwebwx-bin/webwxsync?sid=DPBMWBFsFsy1cid7&skey=@crypt_9e7748df_5664f15bf3836bb0f012e20b5887ff99&pass_ticket=su28XLgcvMetzNMspEByIz0R08gBtPvRbYAiLaAc9TXs9rFtzaUbb1vgB4VHljmc (Caused by NewConnectionError('<urllib3.connection.VerifiedHTTPSConnection object at 0x7f909ecd0690>: Failed to establish a new connection: [Errno -2] Name or service not known',))

Traceback (most recent call last):
  File "/home/ubuntu/test/ItChat/itchat/components/login.py", line 254, in maintain_loop
    msgList, contactList = self.get_msg()
  File "/home/ubuntu/test/ItChat/itchat/components/login.py", line 336, in get_msg
    r = self.s.post(url, data=json.dumps(data), headers=headers, timeout=config.TIMEOUT)
  File "/home/ubuntu/.local/lib/python2.7/site-packages/requests/sessions.py", line 572, in post
    return self.request('POST', url, data=data, json=json, **kwargs)
  File "/home/ubuntu/.local/lib/python2.7/site-packages/requests/sessions.py", line 524, in request
    resp = self.send(prep, **send_kwargs)
  File "/home/ubuntu/.local/lib/python2.7/site-packages/requests/sessions.py", line 637, in send
    r = adapter.send(request, **kwargs)
  File "/home/ubuntu/.local/lib/python2.7/site-packages/requests/adapters.py", line 516, in send
    raise ConnectionError(e, request=request)
ConnectionError: HTTPSConnectionPool(host='wx.qq.com', port=443): Max retries exceeded with url: /cgi-bin/mmwebwx-bin/webwxsync?sid=DPBMWBFsFsy1cid7&skey=@crypt_9e7748df_5664f15bf3836bb0f012e20b5887ff99&pass_ticket=su28XLgcvMetzNMspEByIz0R08gBtPvRbYAiLaAc9TXs9rFtzaUbb1vgB4VHljmc (Caused by NewConnectionError('<urllib3.connection.VerifiedHTTPSConnection object at 0x7f9067552c90>: Failed to establish a new connection: [Errno -2] Name or service not known',))

Traceback (most recent call last):
  File "/home/ubuntu/test/ItChat/itchat/components/login.py", line 254, in maintain_loop
    msgList, contactList = self.get_msg()
  File "/home/ubuntu/test/ItChat/itchat/components/login.py", line 336, in get_msg
    r = self.s.post(url, data=json.dumps(data), headers=headers, timeout=config.TIMEOUT)
  File "/home/ubuntu/.local/lib/python2.7/site-packages/requests/sessions.py", line 572, in post
    return self.request('POST', url, data=data, json=json, **kwargs)
  File "/home/ubuntu/.local/lib/python2.7/site-packages/requests/sessions.py", line 524, in request
    resp = self.send(prep, **send_kwargs)
  File "/home/ubuntu/.local/lib/python2.7/site-packages/requests/sessions.py", line 637, in send
    r = adapter.send(request, **kwargs)
  File "/home/ubuntu/.local/lib/python2.7/site-packages/requests/adapters.py", line 516, in send
    raise ConnectionError(e, request=request)
ConnectionError: HTTPSConnectionPool(host='wx.qq.com', port=443): Max retries exceeded with url: /cgi-bin/mmwebwx-bin/webwxsync?sid=DPBMWBFsFsy1cid7&skey=@crypt_9e7748df_5664f15bf3836bb0f012e20b5887ff99&pass_ticket=su28XLgcvMetzNMspEByIz0R08gBtPvRbYAiLaAc9TXs9rFtzaUbb1vgB4VHljmc (Caused by NewConnectionError('<urllib3.connection.VerifiedHTTPSConnection object at 0x7f907d2d6310>: Failed to establish a new connection: [Errno -2] Name or service not known',))

Traceback (most recent call last):
  File "/home/ubuntu/test/ItChat/itchat/components/login.py", line 254, in maintain_loop
    msgList, contactList = self.get_msg()
  File "/home/ubuntu/test/ItChat/itchat/components/login.py", line 336, in get_msg
    r = self.s.post(url, data=json.dumps(data), headers=headers, timeout=config.TIMEOUT)
  File "/home/ubuntu/.local/lib/python2.7/site-packages/requests/sessions.py", line 572, in post
    return self.request('POST', url, data=data, json=json, **kwargs)
  File "/home/ubuntu/.local/lib/python2.7/site-packages/requests/sessions.py", line 524, in request
    resp = self.send(prep, **send_kwargs)
  File "/home/ubuntu/.local/lib/python2.7/site-packages/requests/sessions.py", line 637, in send
    r = adapter.send(request, **kwargs)
  File "/home/ubuntu/.local/lib/python2.7/site-packages/requests/adapters.py", line 516, in send
    raise ConnectionError(e, request=request)
ConnectionError: HTTPSConnectionPool(host='wx.qq.com', port=443): Max retries exceeded with url: /cgi-bin/mmwebwx-bin/webwxsync?sid=DPBMWBFsFsy1cid7&skey=@crypt_9e7748df_5664f15bf3836bb0f012e20b5887ff99&pass_ticket=su28XLgcvMetzNMspEByIz0R08gBtPvRbYAiLaAc9TXs9rFtzaUbb1vgB4VHljmc (Caused by NewConnectionError('<urllib3.connection.VerifiedHTTPSConnection object at 0x7f906bdcc9d0>: Failed to establish a new connection: [Errno -2] Name or service not known',))

Traceback (most recent call last):
  File "/home/ubuntu/test/ItChat/itchat/components/login.py", line 254, in maintain_loop
    msgList, contactList = self.get_msg()
  File "/home/ubuntu/test/ItChat/itchat/components/login.py", line 336, in get_msg
    r = self.s.post(url, data=json.dumps(data), headers=headers, timeout=config.TIMEOUT)
  File "/home/ubuntu/.local/lib/python2.7/site-packages/requests/sessions.py", line 572, in post
    return self.request('POST', url, data=data, json=json, **kwargs)
  File "/home/ubuntu/.local/lib/python2.7/site-packages/requests/sessions.py", line 524, in request
    resp = self.send(prep, **send_kwargs)
  File "/home/ubuntu/.local/lib/python2.7/site-packages/requests/sessions.py", line 637, in send
    r = adapter.send(request, **kwargs)
  File "/home/ubuntu/.local/lib/python2.7/site-packages/requests/adapters.py", line 516, in send
    raise ConnectionError(e, request=request)
ConnectionError: HTTPSConnectionPool(host='wx.qq.com', port=443): Max retries exceeded with url: /cgi-bin/mmwebwx-bin/webwxsync?sid=DPBMWBFsFsy1cid7&skey=@crypt_9e7748df_5664f15bf3836bb0f012e20b5887ff99&pass_ticket=su28XLgcvMetzNMspEByIz0R08gBtPvRbYAiLaAc9TXs9rFtzaUbb1vgB4VHljmc (Caused by NewConnectionError('<urllib3.connection.VerifiedHTTPSConnection object at 0x7f906cd0ab90>: Failed to establish a new connection: [Errno -2] Name or service not known',))

Traceback (most recent call last):
  File "/home/ubuntu/test/ItChat/itchat/components/login.py", line 248, in maintain_loop
    i = sync_check(self)
  File "/home/ubuntu/test/ItChat/itchat/components/login.py", line 308, in sync_check
    if not isinstance(e.args[0].args[1], BadStatusLine):
IndexError: tuple index out of range

Traceback (most recent call last):
  File "/home/ubuntu/test/ItChat/itchat/components/login.py", line 248, in maintain_loop
    i = sync_check(self)
  File "/home/ubuntu/test/ItChat/itchat/components/login.py", line 308, in sync_check
    if not isinstance(e.args[0].args[1], BadStatusLine):
IndexError: tuple index out of range

Traceback (most recent call last):
  File "/home/ubuntu/test/ItChat/itchat/components/login.py", line 248, in maintain_loop
    i = sync_check(self)
  File "/home/ubuntu/test/ItChat/itchat/components/login.py", line 308, in sync_check
    if not isinstance(e.args[0].args[1], BadStatusLine):
IndexError: tuple index out of range

Traceback (most recent call last):
  File "/home/ubuntu/test/ItChat/itchat/components/login.py", line 248, in maintain_loop
    i = sync_check(self)
  File "/home/ubuntu/test/ItChat/itchat/components/login.py", line 308, in sync_check
    if not isinstance(e.args[0].args[1], BadStatusLine):
IndexError: tuple index out of range

Traceback (most recent call last):
  File "/home/ubuntu/test/ItChat/itchat/components/login.py", line 248, in maintain_loop
    i = sync_check(self)
  File "/home/ubuntu/test/ItChat/itchat/components/login.py", line 308, in sync_check
    if not isinstance(e.args[0].args[1], BadStatusLine):
IndexError: tuple index out of range

Traceback (most recent call last):
  File "/home/ubuntu/test/ItChat/itchat/components/login.py", line 248, in maintain_loop
    i = sync_check(self)
  File "/home/ubuntu/test/ItChat/itchat/components/login.py", line 308, in sync_check
    if not isinstance(e.args[0].args[1], BadStatusLine):
IndexError: tuple index out of range

Traceback (most recent call last):
  File "/home/ubuntu/test/ItChat/itchat/components/login.py", line 248, in maintain_loop
    i = sync_check(self)
  File "/home/ubuntu/test/ItChat/itchat/components/login.py", line 308, in sync_check
    if not isinstance(e.args[0].args[1], BadStatusLine):
IndexError: tuple index out of range

Traceback (most recent call last):
  File "/home/ubuntu/test/ItChat/itchat/components/login.py", line 248, in maintain_loop
    i = sync_check(self)
  File "/home/ubuntu/test/ItChat/itchat/components/login.py", line 308, in sync_check
    if not isinstance(e.args[0].args[1], BadStatusLine):
IndexError: tuple index out of range

Traceback (most recent call last):
  File "/home/ubuntu/test/ItChat/itchat/components/login.py", line 248, in maintain_loop
    i = sync_check(self)
  File "/home/ubuntu/test/ItChat/itchat/components/login.py", line 308, in sync_check
    if not isinstance(e.args[0].args[1], BadStatusLine):
IndexError: tuple index out of range

Traceback (most recent call last):
  File "/home/ubuntu/test/ItChat/itchat/components/login.py", line 248, in maintain_loop
    i = sync_check(self)
  File "/home/ubuntu/test/ItChat/itchat/components/login.py", line 308, in sync_check
    if not isinstance(e.args[0].args[1], BadStatusLine):
IndexError: tuple index out of range

Traceback (most recent call last):
  File "/home/ubuntu/test/ItChat/itchat/components/login.py", line 248, in maintain_loop
    i = sync_check(self)
  File "/home/ubuntu/test/ItChat/itchat/components/login.py", line 308, in sync_check
    if not isinstance(e.args[0].args[1], BadStatusLine):
IndexError: tuple index out of range

Traceback (most recent call last):
  File "/home/ubuntu/test/ItChat/itchat/components/login.py", line 248, in maintain_loop
    i = sync_check(self)
  File "/home/ubuntu/test/ItChat/itchat/components/login.py", line 308, in sync_check
    if not isinstance(e.args[0].args[1], BadStatusLine):
IndexError: tuple index out of range

Traceback (most recent call last):
  File "/home/ubuntu/test/ItChat/itchat/components/login.py", line 248, in maintain_loop
    i = sync_check(self)
  File "/home/ubuntu/test/ItChat/itchat/components/login.py", line 308, in sync_check
    if not isinstance(e.args[0].args[1], BadStatusLine):
IndexError: tuple index out of range

Traceback (most recent call last):
  File "/home/ubuntu/test/ItChat/itchat/components/login.py", line 248, in maintain_loop
    i = sync_check(self)
  File "/home/ubuntu/test/ItChat/itchat/components/login.py", line 308, in sync_check
    if not isinstance(e.args[0].args[1], BadStatusLine):
IndexError: tuple index out of range

Traceback (most recent call last):
  File "/home/ubuntu/test/ItChat/itchat/components/login.py", line 248, in maintain_loop
    i = sync_check(self)
  File "/home/ubuntu/test/ItChat/itchat/components/login.py", line 308, in sync_check
    if not isinstance(e.args[0].args[1], BadStatusLine):
IndexError: tuple index out of range

Traceback (most recent call last):
  File "/home/ubuntu/test/ItChat/itchat/components/login.py", line 248, in maintain_loop
    i = sync_check(self)
  File "/home/ubuntu/test/ItChat/itchat/components/login.py", line 308, in sync_check
    if not isinstance(e.args[0].args[1], BadStatusLine):
IndexError: tuple index out of range

Traceback (most recent call last):
  File "/home/ubuntu/test/ItChat/itchat/components/login.py", line 248, in maintain_loop
    i = sync_check(self)
  File "/home/ubuntu/test/ItChat/itchat/components/login.py", line 308, in sync_check
    if not isinstance(e.args[0].args[1], BadStatusLine):
IndexError: tuple index out of range

Traceback (most recent call last):
  File "/home/ubuntu/test/ItChat/itchat/components/login.py", line 248, in maintain_loop
    i = sync_check(self)
  File "/home/ubuntu/test/ItChat/itchat/components/login.py", line 308, in sync_check
    if not isinstance(e.args[0].args[1], BadStatusLine):
IndexError: tuple index out of range

Traceback (most recent call last):
  File "/home/ubuntu/test/ItChat/itchat/components/login.py", line 248, in maintain_loop
    i = sync_check(self)
  File "/home/ubuntu/test/ItChat/itchat/components/login.py", line 308, in sync_check
    if not isinstance(e.args[0].args[1], BadStatusLine):
IndexError: tuple index out of range

Traceback (most recent call last):
  File "/home/ubuntu/test/ItChat/itchat/components/login.py", line 248, in maintain_loop
    i = sync_check(self)
  File "/home/ubuntu/test/ItChat/itchat/components/login.py", line 308, in sync_check
    if not isinstance(e.args[0].args[1], BadStatusLine):
IndexError: tuple index out of range

Traceback (most recent call last):
  File "/home/ubuntu/test/ItChat/itchat/components/login.py", line 248, in maintain_loop
    i = sync_check(self)
  File "/home/ubuntu/test/ItChat/itchat/components/login.py", line 308, in sync_check
    if not isinstance(e.args[0].args[1], BadStatusLine):
IndexError: tuple index out of range

Traceback (most recent call last):
  File "/home/ubuntu/test/ItChat/itchat/components/login.py", line 248, in maintain_loop
    i = sync_check(self)
  File "/home/ubuntu/test/ItChat/itchat/components/login.py", line 308, in sync_check
    if not isinstance(e.args[0].args[1], BadStatusLine):
IndexError: tuple index out of range

Traceback (most recent call last):
  File "/home/ubuntu/test/ItChat/itchat/components/login.py", line 248, in maintain_loop
    i = sync_check(self)
  File "/home/ubuntu/test/ItChat/itchat/components/login.py", line 308, in sync_check
    if not isinstance(e.args[0].args[1], BadStatusLine):
IndexError: tuple index out of range

Traceback (most recent call last):
  File "/home/ubuntu/test/ItChat/itchat/components/login.py", line 248, in maintain_loop
    i = sync_check(self)
  File "/home/ubuntu/test/ItChat/itchat/components/login.py", line 308, in sync_check
    if not isinstance(e.args[0].args[1], BadStatusLine):
IndexError: tuple index out of range

Traceback (most recent call last):
  File "/home/ubuntu/test/ItChat/itchat/components/login.py", line 248, in maintain_loop
    i = sync_check(self)
  File "/home/ubuntu/test/ItChat/itchat/components/login.py", line 308, in sync_check
    if not isinstance(e.args[0].args[1], BadStatusLine):
IndexError: tuple index out of range

Traceback (most recent call last):
  File "/home/ubuntu/test/ItChat/itchat/components/login.py", line 248, in maintain_loop
    i = sync_check(self)
  File "/home/ubuntu/test/ItChat/itchat/components/login.py", line 308, in sync_check
    if not isinstance(e.args[0].args[1], BadStatusLine):
IndexError: tuple index out of range

Traceback (most recent call last):
  File "/home/ubuntu/test/ItChat/itchat/components/login.py", line 248, in maintain_loop
    i = sync_check(self)
  File "/home/ubuntu/test/ItChat/itchat/components/login.py", line 308, in sync_check
    if not isinstance(e.args[0].args[1], BadStatusLine):
IndexError: tuple index out of range

Traceback (most recent call last):
  File "/home/ubuntu/test/ItChat/itchat/components/login.py", line 248, in maintain_loop
    i = sync_check(self)
  File "/home/ubuntu/test/ItChat/itchat/components/login.py", line 308, in sync_check
    if not isinstance(e.args[0].args[1], BadStatusLine):
IndexError: tuple index out of range

Traceback (most recent call last):
  File "/home/ubuntu/test/ItChat/itchat/components/login.py", line 248, in maintain_loop
    i = sync_check(self)
  File "/home/ubuntu/test/ItChat/itchat/components/login.py", line 308, in sync_check
    if not isinstance(e.args[0].args[1], BadStatusLine):
IndexError: tuple index out of range

Traceback (most recent call last):
  File "/home/ubuntu/test/ItChat/itchat/components/login.py", line 248, in maintain_loop
    i = sync_check(self)
  File "/home/ubuntu/test/ItChat/itchat/components/login.py", line 308, in sync_check
    if not isinstance(e.args[0].args[1], BadStatusLine):
IndexError: tuple index out of range

Traceback (most recent call last):
  File "/home/ubuntu/test/ItChat/itchat/components/login.py", line 248, in maintain_loop
    i = sync_check(self)
  File "/home/ubuntu/test/ItChat/itchat/components/login.py", line 308, in sync_check
    if not isinstance(e.args[0].args[1], BadStatusLine):
IndexError: tuple index out of range

Traceback (most recent call last):
  File "/home/ubuntu/test/ItChat/itchat/components/login.py", line 248, in maintain_loop
    i = sync_check(self)
  File "/home/ubuntu/test/ItChat/itchat/components/login.py", line 308, in sync_check
    if not isinstance(e.args[0].args[1], BadStatusLine):
IndexError: tuple index out of range

Traceback (most recent call last):
  File "/home/ubuntu/test/ItChat/itchat/components/login.py", line 248, in maintain_loop
    i = sync_check(self)
  File "/home/ubuntu/test/ItChat/itchat/components/login.py", line 308, in sync_check
    if not isinstance(e.args[0].args[1], BadStatusLine):
IndexError: tuple index out of range

Traceback (most recent call last):
  File "/home/ubuntu/test/ItChat/itchat/components/login.py", line 248, in maintain_loop
    i = sync_check(self)
  File "/home/ubuntu/test/ItChat/itchat/components/login.py", line 308, in sync_check
    if not isinstance(e.args[0].args[1], BadStatusLine):
IndexError: tuple index out of range

Traceback (most recent call last):
  File "/home/ubuntu/test/ItChat/itchat/components/login.py", line 248, in maintain_loop
    i = sync_check(self)
  File "/home/ubuntu/test/ItChat/itchat/components/login.py", line 308, in sync_check
    if not isinstance(e.args[0].args[1], BadStatusLine):
IndexError: tuple index out of range

Traceback (most recent call last):
  File "/home/ubuntu/test/ItChat/itchat/components/login.py", line 248, in maintain_loop
    i = sync_check(self)
  File "/home/ubuntu/test/ItChat/itchat/components/login.py", line 308, in sync_check
    if not isinstance(e.args[0].args[1], BadStatusLine):
IndexError: tuple index out of range

Traceback (most recent call last):
  File "/home/ubuntu/test/ItChat/itchat/components/login.py", line 248, in maintain_loop
    i = sync_check(self)
  File "/home/ubuntu/test/ItChat/itchat/components/login.py", line 308, in sync_check
    if not isinstance(e.args[0].args[1], BadStatusLine):
IndexError: tuple index out of range

Traceback (most recent call last):
  File "/home/ubuntu/test/ItChat/itchat/components/login.py", line 248, in maintain_loop
    i = sync_check(self)
  File "/home/ubuntu/test/ItChat/itchat/components/login.py", line 308, in sync_check
    if not isinstance(e.args[0].args[1], BadStatusLine):
IndexError: tuple index out of range

Traceback (most recent call last):
  File "/home/ubuntu/test/ItChat/itchat/components/login.py", line 248, in maintain_loop
    i = sync_check(self)
  File "/home/ubuntu/test/ItChat/itchat/components/login.py", line 308, in sync_check
    if not isinstance(e.args[0].args[1], BadStatusLine):
IndexError: tuple index out of range

Traceback (most recent call last):
  File "/home/ubuntu/test/ItChat/itchat/components/login.py", line 248, in maintain_loop
    i = sync_check(self)
  File "/home/ubuntu/test/ItChat/itchat/components/login.py", line 308, in sync_check
    if not isinstance(e.args[0].args[1], BadStatusLine):
IndexError: tuple index out of range

Traceback (most recent call last):
  File "/home/ubuntu/test/ItChat/itchat/components/login.py", line 248, in maintain_loop
    i = sync_check(self)
  File "/home/ubuntu/test/ItChat/itchat/components/login.py", line 308, in sync_check
    if not isinstance(e.args[0].args[1], BadStatusLine):
IndexError: tuple index out of range

Traceback (most recent call last):
  File "/home/ubuntu/test/ItChat/itchat/components/login.py", line 248, in maintain_loop
    i = sync_check(self)
  File "/home/ubuntu/test/ItChat/itchat/components/login.py", line 308, in sync_check
    if not isinstance(e.args[0].args[1], BadStatusLine):
IndexError: tuple index out of range

Traceback (most recent call last):
  File "/home/ubuntu/test/ItChat/itchat/components/login.py", line 248, in maintain_loop
    i = sync_check(self)
  File "/home/ubuntu/test/ItChat/itchat/components/login.py", line 308, in sync_check
    if not isinstance(e.args[0].args[1], BadStatusLine):
IndexError: tuple index out of range

Traceback (most recent call last):
  File "/home/ubuntu/test/ItChat/itchat/components/login.py", line 248, in maintain_loop
    i = sync_check(self)
  File "/home/ubuntu/test/ItChat/itchat/components/login.py", line 308, in sync_check
    if not isinstance(e.args[0].args[1], BadStatusLine):
IndexError: tuple index out of range

Traceback (most recent call last):
  File "/home/ubuntu/test/ItChat/itchat/components/login.py", line 248, in maintain_loop
    i = sync_check(self)
  File "/home/ubuntu/test/ItChat/itchat/components/login.py", line 308, in sync_check
    if not isinstance(e.args[0].args[1], BadStatusLine):
IndexError: tuple index out of range

Traceback (most recent call last):
  File "/home/ubuntu/test/ItChat/itchat/components/login.py", line 248, in maintain_loop
    i = sync_check(self)
  File "/home/ubuntu/test/ItChat/itchat/components/login.py", line 308, in sync_check
    if not isinstance(e.args[0].args[1], BadStatusLine):
IndexError: tuple index out of range

Traceback (most recent call last):
  File "/home/ubuntu/test/ItChat/itchat/components/login.py", line 248, in maintain_loop
    i = sync_check(self)
  File "/home/ubuntu/test/ItChat/itchat/components/login.py", line 308, in sync_check
    if not isinstance(e.args[0].args[1], BadStatusLine):
IndexError: tuple index out of range

Traceback (most recent call last):
  File "/home/ubuntu/test/ItChat/itchat/components/login.py", line 248, in maintain_loop
    i = sync_check(self)
  File "/home/ubuntu/test/ItChat/itchat/components/login.py", line 308, in sync_check
    if not isinstance(e.args[0].args[1], BadStatusLine):
IndexError: tuple index out of range

Traceback (most recent call last):
  File "/home/ubuntu/test/ItChat/itchat/components/login.py", line 248, in maintain_loop
    i = sync_check(self)
  File "/home/ubuntu/test/ItChat/itchat/components/login.py", line 308, in sync_check
    if not isinstance(e.args[0].args[1], BadStatusLine):
IndexError: tuple index out of range

Traceback (most recent call last):
  File "/home/ubuntu/test/ItChat/itchat/components/login.py", line 248, in maintain_loop
    i = sync_check(self)
  File "/home/ubuntu/test/ItChat/itchat/components/login.py", line 308, in sync_check
    if not isinstance(e.args[0].args[1], BadStatusLine):
IndexError: tuple index out of range

Traceback (most recent call last):
  File "/home/ubuntu/test/ItChat/itchat/components/login.py", line 248, in maintain_loop
    i = sync_check(self)
  File "/home/ubuntu/test/ItChat/itchat/components/login.py", line 308, in sync_check
    if not isinstance(e.args[0].args[1], BadStatusLine):
IndexError: tuple index out of range

Traceback (most recent call last):
  File "/home/ubuntu/test/ItChat/itchat/components/login.py", line 248, in maintain_loop
    i = sync_check(self)
  File "/home/ubuntu/test/ItChat/itchat/components/login.py", line 308, in sync_check
    if not isinstance(e.args[0].args[1], BadStatusLine):
IndexError: tuple index out of range

Traceback (most recent call last):
  File "/home/ubuntu/test/ItChat/itchat/components/login.py", line 248, in maintain_loop
    i = sync_check(self)
  File "/home/ubuntu/test/ItChat/itchat/components/login.py", line 308, in sync_check
    if not isinstance(e.args[0].args[1], BadStatusLine):
IndexError: tuple index out of range

Traceback (most recent call last):
  File "/home/ubuntu/test/ItChat/itchat/components/login.py", line 248, in maintain_loop
    i = sync_check(self)
  File "/home/ubuntu/test/ItChat/itchat/components/login.py", line 308, in sync_check
    if not isinstance(e.args[0].args[1], BadStatusLine):
IndexError: tuple index out of range

Traceback (most recent call last):
  File "/home/ubuntu/test/ItChat/itchat/components/login.py", line 248, in maintain_loop
    i = sync_check(self)
  File "/home/ubuntu/test/ItChat/itchat/components/login.py", line 308, in sync_check
    if not isinstance(e.args[0].args[1], BadStatusLine):
IndexError: tuple index out of range

Traceback (most recent call last):
  File "/home/ubuntu/test/ItChat/itchat/components/login.py", line 248, in maintain_loop
    i = sync_check(self)
  File "/home/ubuntu/test/ItChat/itchat/components/login.py", line 308, in sync_check
    if not isinstance(e.args[0].args[1], BadStatusLine):
IndexError: tuple index out of range

Traceback (most recent call last):
  File "/home/ubuntu/test/ItChat/itchat/components/login.py", line 248, in maintain_loop
    i = sync_check(self)
  File "/home/ubuntu/test/ItChat/itchat/components/login.py", line 308, in sync_check
    if not isinstance(e.args[0].args[1], BadStatusLine):
IndexError: tuple index out of range

Traceback (most recent call last):
  File "/home/ubuntu/test/ItChat/itchat/components/login.py", line 248, in maintain_loop
    i = sync_check(self)
  File "/home/ubuntu/test/ItChat/itchat/components/login.py", line 308, in sync_check
    if not isinstance(e.args[0].args[1], BadStatusLine):
IndexError: tuple index out of range

Traceback (most recent call last):
  File "/home/ubuntu/test/ItChat/itchat/components/login.py", line 248, in maintain_loop
    i = sync_check(self)
  File "/home/ubuntu/test/ItChat/itchat/components/login.py", line 308, in sync_check
    if not isinstance(e.args[0].args[1], BadStatusLine):
IndexError: tuple index out of range

Traceback (most recent call last):
  File "/home/ubuntu/test/ItChat/itchat/components/login.py", line 248, in maintain_loop
    i = sync_check(self)
  File "/home/ubuntu/test/ItChat/itchat/components/login.py", line 308, in sync_check
    if not isinstance(e.args[0].args[1], BadStatusLine):
IndexError: tuple index out of range

Traceback (most recent call last):
  File "/home/ubuntu/test/ItChat/itchat/components/login.py", line 248, in maintain_loop
    i = sync_check(self)
  File "/home/ubuntu/test/ItChat/itchat/components/login.py", line 308, in sync_check
    if not isinstance(e.args[0].args[1], BadStatusLine):
IndexError: tuple index out of range

Traceback (most recent call last):
  File "/home/ubuntu/test/ItChat/itchat/components/login.py", line 248, in maintain_loop
    i = sync_check(self)
  File "/home/ubuntu/test/ItChat/itchat/components/login.py", line 308, in sync_check
    if not isinstance(e.args[0].args[1], BadStatusLine):
IndexError: tuple index out of range

Traceback (most recent call last):
  File "/home/ubuntu/test/ItChat/itchat/components/login.py", line 248, in maintain_loop
    i = sync_check(self)
  File "/home/ubuntu/test/ItChat/itchat/components/login.py", line 308, in sync_check
    if not isinstance(e.args[0].args[1], BadStatusLine):
IndexError: tuple index out of range

Traceback (most recent call last):
  File "/home/ubuntu/test/ItChat/itchat/components/login.py", line 248, in maintain_loop
    i = sync_check(self)
  File "/home/ubuntu/test/ItChat/itchat/components/login.py", line 308, in sync_check
    if not isinstance(e.args[0].args[1], BadStatusLine):
IndexError: tuple index out of range

Traceback (most recent call last):
  File "/home/ubuntu/test/ItChat/itchat/components/login.py", line 248, in maintain_loop
    i = sync_check(self)
  File "/home/ubuntu/test/ItChat/itchat/components/login.py", line 308, in sync_check
    if not isinstance(e.args[0].args[1], BadStatusLine):
IndexError: tuple index out of range

Traceback (most recent call last):
  File "/home/ubuntu/test/ItChat/itchat/components/login.py", line 248, in maintain_loop
    i = sync_check(self)
  File "/home/ubuntu/test/ItChat/itchat/components/login.py", line 308, in sync_check
    if not isinstance(e.args[0].args[1], BadStatusLine):
IndexError: tuple index out of range

Traceback (most recent call last):
  File "/home/ubuntu/test/ItChat/itchat/components/login.py", line 248, in maintain_loop
    i = sync_check(self)
  File "/home/ubuntu/test/ItChat/itchat/components/login.py", line 308, in sync_check
    if not isinstance(e.args[0].args[1], BadStatusLine):
IndexError: tuple index out of range

Traceback (most recent call last):
  File "/home/ubuntu/test/ItChat/itchat/components/login.py", line 248, in maintain_loop
    i = sync_check(self)
  File "/home/ubuntu/test/ItChat/itchat/components/login.py", line 308, in sync_check
    if not isinstance(e.args[0].args[1], BadStatusLine):
IndexError: tuple index out of range

Traceback (most recent call last):
  File "/home/ubuntu/test/ItChat/itchat/components/login.py", line 248, in maintain_loop
    i = sync_check(self)
  File "/home/ubuntu/test/ItChat/itchat/components/login.py", line 308, in sync_check
    if not isinstance(e.args[0].args[1], BadStatusLine):
IndexError: tuple index out of range

LOG OUT!
LOG OUT!
Traceback (most recent call last):
  File "/home/ubuntu/test/ItChat/itchat/components/login.py", line 248, in maintain_loop
    i = sync_check(self)
  File "/home/ubuntu/test/ItChat/itchat/components/login.py", line 308, in sync_check
    if not isinstance(e.args[0].args[1], BadStatusLine):
IndexError: tuple index out of range

LOG OUT!
Traceback (most recent call last):
  File "/home/ubuntu/test/ItChat/itchat/components/login.py", line 248, in maintain_loop
    i = sync_check(self)
  File "/home/ubuntu/test/ItChat/itchat/components/login.py", line 308, in sync_check
    if not isinstance(e.args[0].args[1], BadStatusLine):
IndexError: tuple index out of range

Traceback (most recent call last):
  File "/home/ubuntu/test/ItChat/itchat/components/login.py", line 248, in maintain_loop
    i = sync_check(self)
  File "/home/ubuntu/test/ItChat/itchat/components/login.py", line 308, in sync_check
    if not isinstance(e.args[0].args[1], BadStatusLine):
IndexError: tuple index out of range

LOG OUT!
LOG OUT!
Traceback (most recent call last):
  File "/home/ubuntu/test/ItChat/itchat/components/login.py", line 248, in maintain_loop
    i = sync_check(self)
  File "/home/ubuntu/test/ItChat/itchat/components/login.py", line 308, in sync_check
    if not isinstance(e.args[0].args[1], BadStatusLine):
IndexError: tuple index out of range

LOG OUT!
Traceback (most recent call last):
  File "/home/ubuntu/test/ItChat/itchat/components/login.py", line 248, in maintain_loop
    i = sync_check(self)
  File "/home/ubuntu/test/ItChat/itchat/components/login.py", line 308, in sync_check
    if not isinstance(e.args[0].args[1], BadStatusLine):
IndexError: tuple index out of range

Traceback (most recent call last):
  File "/home/ubuntu/test/ItChat/itchat/components/login.py", line 248, in maintain_loop
    i = sync_check(self)
  File "/home/ubuntu/test/ItChat/itchat/components/login.py", line 308, in sync_check
    if not isinstance(e.args[0].args[1], BadStatusLine):
IndexError: tuple index out of range

Traceback (most recent call last):
  File "/home/ubuntu/test/ItChat/itchat/components/login.py", line 248, in maintain_loop
    i = sync_check(self)
  File "/home/ubuntu/test/ItChat/itchat/components/login.py", line 308, in sync_check
    if not isinstance(e.args[0].args[1], BadStatusLine):
IndexError: tuple index out of range

Traceback (most recent call last):
  File "/home/ubuntu/test/ItChat/itchat/components/login.py", line 248, in maintain_loop
    i = sync_check(self)
  File "/home/ubuntu/test/ItChat/itchat/components/login.py", line 308, in sync_check
    if not isinstance(e.args[0].args[1], BadStatusLine):
IndexError: tuple index out of range

LOG OUT!
LOG OUT!
LOG OUT!
Traceback (most recent call last):
  File "/home/ubuntu/test/ItChat/itchat/components/login.py", line 248, in maintain_loop
    i = sync_check(self)
  File "/home/ubuntu/test/ItChat/itchat/components/login.py", line 308, in sync_check
    if not isinstance(e.args[0].args[1], BadStatusLine):
IndexError: tuple index out of range

LOG OUT!
LOG OUT!
Traceback (most recent call last):
  File "/home/ubuntu/test/ItChat/itchat/components/login.py", line 248, in maintain_loop
    i = sync_check(self)
  File "/home/ubuntu/test/ItChat/itchat/components/login.py", line 308, in sync_check
    if not isinstance(e.args[0].args[1], BadStatusLine):
IndexError: tuple index out of range

Traceback (most recent call last):
  File "/home/ubuntu/test/ItChat/itchat/components/login.py", line 248, in maintain_loop
    i = sync_check(self)
  File "/home/ubuntu/test/ItChat/itchat/components/login.py", line 308, in sync_check
    if not isinstance(e.args[0].args[1], BadStatusLine):
IndexError: tuple index out of range

Traceback (most recent call last):
  File "/home/ubuntu/test/ItChat/itchat/components/login.py", line 248, in maintain_loop
    i = sync_check(self)
  File "/home/ubuntu/test/ItChat/itchat/components/login.py", line 308, in sync_check
    if not isinstance(e.args[0].args[1], BadStatusLine):
IndexError: tuple index out of range

Traceback (most recent call last):
  File "/home/ubuntu/test/ItChat/itchat/components/login.py", line 248, in maintain_loop
    i = sync_check(self)
  File "/home/ubuntu/test/ItChat/itchat/components/login.py", line 308, in sync_check
    if not isinstance(e.args[0].args[1], BadStatusLine):
IndexError: tuple index out of range

Traceback (most recent call last):
  File "/home/ubuntu/test/ItChat/itchat/utils.py", line 130, in test_connect
    r = requests.get(config.BASE_URL)
  File "/home/ubuntu/.local/lib/python2.7/site-packages/requests/api.py", line 75, in get
    return request('get', url, params=params, **kwargs)
  File "/home/ubuntu/.local/lib/python2.7/site-packages/requests/api.py", line 60, in request
    return session.request(method=method, url=url, **kwargs)
  File "/home/ubuntu/.local/lib/python2.7/site-packages/requests/sessions.py", line 524, in request
    resp = self.send(prep, **send_kwargs)
  File "/home/ubuntu/.local/lib/python2.7/site-packages/requests/sessions.py", line 637, in send
    r = adapter.send(request, **kwargs)
  File "/home/ubuntu/.local/lib/python2.7/site-packages/requests/adapters.py", line 516, in send
    raise ConnectionError(e, request=request)
ConnectionError: HTTPSConnectionPool(host='login.weixin.qq.com', port=443): Max retries exceeded with url: / (Caused by NewConnectionError('<urllib3.connection.VerifiedHTTPSConnection object at 0x7f90b5629910>: Failed to establish a new connection: [Errno -2] Name or service not known',))

You can't get access to internet or wechat domain, so exit.
{u'CAD_CNY': {u'val': 5.247295}}
5.247295
LOG OUT!
LOG OUT!
LOG OUT!
Exception in thread Thread-7 (most likely raised during interpreter shutdown):
 Exception in thread Thread-19 (most likely raised during interpreter shutdown):
Traceback (most recent call last):
  File "/usr/lib/python2.7/threading.py", line 801, in __bootstrap_inner
  File "/usr/lib/python2.7/threading.py", line 754, in run
  File "/home/ubuntu/test/ItChat/itchat/components/login.py", line 271, in maintain_loop
<type 'exceptions.AttributeError'>: 'NoneType' object has no attribute 'exceptions'
Exception in thread Thread-35 (most likely raised during interpreter shutdown):
Traceback (most recent call last):
  File "/usr/lib/python2.7/threading.py", line 801, in __bootstrap_inner
  File "/usr/lib/python2.7/threading.py", line 754, in run
  File "/home/ubuntu/test/ItChat/itchat/components/login.py", line 271, in maintain_loop
<type 'exceptions.AttributeError'>: 'NoneType' object has no attribute 'exceptions'
Exception in thread Thread-18 (most likely raised during interpreter shutdown):
Traceback (most recent call last):
  File "/usr/lib/python2.7/threading.py", line 801, in __bootstrap_inner
  File "/usr/lib/python2.7/threading.py", line 754, in run
  File "/home/ubuntu/test/ItChat/itchat/components/login.py", line 271, in maintain_loop
<type 'exceptions.AttributeError'>: 'NoneType' object has no attribute 'exceptions'
Traceback (most recent call last):
  File "/usr/lib/python2.7/threading.py", line 801, in __bootstrap_inner
  File "/usr/lib/python2.7/threading.py", line 754, in run
  File "/home/ubuntu/test/ItChat/itchat/components/login.py", line 275, in maintain_loop
  File "/usr/lib/python2.7/traceback.py", line 242, in format_exc
  File "/usr/lib/python2.7/traceback.py", line 141, in format_exception
<type 'exceptions.TypeError'>: 'NoneType' object is not callable
Exception in thread Thread-17 (most likely raised during interpreter shutdown):
Traceback (most recent call last):
  File "/usr/lib/python2.7/threading.py", line 801, in __bootstrap_inner
  File "/usr/lib/python2.7/threading.py", line 754, in run
  File "/home/ubuntu/test/ItChat/itchat/components/login.py", line 275, in maintain_loop
  File "/usr/lib/python2.7/traceback.py", line 242, in format_exc
  File "/usr/lib/python2.7/traceback.py", line 141, in format_exception
  File "/usr/lib/python2.7/traceback.py", line 76, in format_tb
  File "/usr/lib/python2.7/traceback.py", line 101, in extract_tb
<type 'exceptions.AttributeError'>: 'NoneType' object has no attribute 'getline'
Exception in thread Thread-28 (most likely raised during interpreter shutdown):
Traceback (most recent call last):
  File "/usr/lib/python2.7/threading.py", line 801, in __bootstrap_inner
  File "/usr/lib/python2.7/threading.py", line 754, in run
  File "/home/ubuntu/test/ItChat/itchat/components/login.py", line 284, in maintain_loop
  File "/usr/lib/python2.7/logging/__init__.py", line 1174, in info
  File "/usr/lib/python2.7/logging/__init__.py", line 1284, in _log
  File "/usr/lib/python2.7/logging/__init__.py", line 1245, in findCaller
<type 'exceptions.TypeError'>: 'NoneType' object is not callable
Exception in thread Thread-49 (most likely raised during interpreter shutdown):
Traceback (most recent call last):
  File "/usr/lib/python2.7/threading.py", line 801, in __bootstrap_inner
  File "/usr/lib/python2.7/threading.py", line 754, in run
  File "/home/ubuntu/test/ItChat/itchat/components/login.py", line 271, in maintain_loop
<type 'exceptions.AttributeError'>: 'NoneType' object has no attribute 'exceptions'
Exception in thread Thread-48 (most likely raised during interpreter shutdown):
Traceback (most recent call last):
  File "/usr/lib/python2.7/threading.py", line 801, in __bootstrap_inner
  File "/usr/lib/python2.7/threading.py", line 754, in run
  File "/home/ubuntu/test/ItChat/itchat/components/login.py", line 271, in maintain_loop
<type 'exceptions.AttributeError'>: 'NoneType' object has no attribute 'exceptions'
